[2023-04-25T14:35:52Z] DEBUG    - Logging set up successfully
[2023-04-25T14:35:52Z] DEBUG    - Running submit: Namespace(version=False, subparser_name='submit', command=<function submit at 0x11c3dd160>, verbose=0, dry_run=False, endpoint_url=None, region='us-west-2', set_default=True, role_arn=None, use_role=True)
[2023-04-25T14:35:52Z] DEBUG    - Root directory: /Volumes/workplace/QuickStart-Builds/quickstart-kubernetes-resource-provider
[2023-04-25T14:35:52Z] DEBUG    - Loading project file '/Volumes/workplace/QuickStart-Builds/quickstart-kubernetes-resource-provider/.rpdk-config'
[2023-04-25T14:35:52Z] DEBUG    - Project file /Volumes/workplace/QuickStart-Builds/quickstart-kubernetes-resource-provider/.rpdk-config not found. Have you run 'init' or in a wrong directory?
Traceback (most recent call last):
  File "/Users/ameighta/.pyenv/versions/3.9.13/envs/primary/lib/python3.9/site-packages/rpdk/core/project.py", line 545, in load
    self.load_settings()
  File "/Users/ameighta/.pyenv/versions/3.9.13/envs/primary/lib/python3.9/site-packages/rpdk/core/project.py", line 218, in load_settings
    with self.settings_path.open("r", encoding="utf-8") as f:
  File "/Users/ameighta/.pyenv/versions/3.9.13/lib/python3.9/pathlib.py", line 1252, in open
    return io.open(self, mode, buffering, encoding, errors, newline,
  File "/Users/ameighta/.pyenv/versions/3.9.13/lib/python3.9/pathlib.py", line 1120, in _opener
    return self._accessor.open(self, flags, mode)
FileNotFoundError: [Errno 2] No such file or directory: '/Volumes/workplace/QuickStart-Builds/quickstart-kubernetes-resource-provider/.rpdk-config'
[2023-04-25T14:35:52Z] DEBUG    - Caught exit recommendation
Traceback (most recent call last):
  File "/Users/ameighta/.pyenv/versions/3.9.13/envs/primary/lib/python3.9/site-packages/rpdk/core/project.py", line 545, in load
    self.load_settings()
  File "/Users/ameighta/.pyenv/versions/3.9.13/envs/primary/lib/python3.9/site-packages/rpdk/core/project.py", line 218, in load_settings
    with self.settings_path.open("r", encoding="utf-8") as f:
  File "/Users/ameighta/.pyenv/versions/3.9.13/lib/python3.9/pathlib.py", line 1252, in open
    return io.open(self, mode, buffering, encoding, errors, newline,
  File "/Users/ameighta/.pyenv/versions/3.9.13/lib/python3.9/pathlib.py", line 1120, in _opener
    return self._accessor.open(self, flags, mode)
FileNotFoundError: [Errno 2] No such file or directory: '/Volumes/workplace/QuickStart-Builds/quickstart-kubernetes-resource-provider/.rpdk-config'

The above exception was the direct cause of the following exception:

Traceback (most recent call last):
  File "/Users/ameighta/.pyenv/versions/3.9.13/envs/primary/lib/python3.9/site-packages/rpdk/core/cli.py", line 100, in main
    args.command(args)
  File "/Users/ameighta/.pyenv/versions/3.9.13/envs/primary/lib/python3.9/site-packages/rpdk/core/submit.py", line 14, in submit
    project.load()
  File "/Users/ameighta/.pyenv/versions/3.9.13/envs/primary/lib/python3.9/site-packages/rpdk/core/project.py", line 547, in load
    self._raise_invalid_project(
  File "/Users/ameighta/.pyenv/versions/3.9.13/envs/primary/lib/python3.9/site-packages/rpdk/core/project.py", line 213, in _raise_invalid_project
    raise InvalidProjectError(msg) from e
rpdk.core.exceptions.InvalidProjectError: Project file /Volumes/workplace/QuickStart-Builds/quickstart-kubernetes-resource-provider/.rpdk-config not found. Have you run 'init' or in a wrong directory?
[2023-04-25T14:35:52Z] CRITICAL - Project file /Volumes/workplace/QuickStart-Builds/quickstart-kubernetes-resource-provider/.rpdk-config not found. Have you run 'init' or in a wrong directory?
